<sdf version='1.6'>
  <world name='default'>
    <light name='sun' type='directional'>
      <cast_shadows>1</cast_shadows>
      <pose frame=''>0 0 10 0 -0 0</pose>
      <diffuse>0.8 0.8 0.8 1</diffuse>
      <specular>0.2 0.2 0.2 1</specular>
      <attenuation>
        <range>1000</range>
        <constant>0.9</constant>
        <linear>0.01</linear>
        <quadratic>0.001</quadratic>
      </attenuation>
      <direction>-0.5 0.1 -0.9</direction>
    </light>
    <model name='iris'>
      <link name='base_link'>
        <pose frame=''>0 0 0 0 -0 0</pose>
        <inertial>
          <pose frame=''>0 0 0 0 -0 0</pose>
          <mass>1.5</mass>
          <inertia>
            <ixx>0.0347563</ixx>
            <ixy>0</ixy>
            <ixz>0</ixz>
            <iyy>0.0458929</iyy>
            <iyz>0</iyz>
            <izz>0.0977</izz>
          </inertia>
        </inertial>
        <collision name='base_link_inertia_collision'>
          <pose frame=''>0 0 0 0 -0 0</pose>
          <geometry>
            <box>
              <size>0.47 0.47 0.11</size>
            </box>
          </geometry>
          <surface>
            <contact>
              <ode>
                <min_depth>0.001</min_depth>
                <max_vel>0</max_vel>
              </ode>
            </contact>
            <friction>
              <ode/>
              <torsional>
                <ode/>
              </torsional>
            </friction>
            <bounce/>
          </surface>
          <max_contacts>10</max_contacts>
        </collision>
        <visual name='base_link_inertia_visual'>
          <pose frame=''>0 0 0 0 -0 0</pose>
          <geometry>
            <mesh>
              <scale>1 1 1</scale>
              <uri>model://rotors_description/meshes/iris.stl</uri>
            </mesh>
          </geometry>
          <material>
            <script>
              <name>Gazebo/DarkGrey</name>
              <uri>file://media/materials/scripts/gazebo.material</uri>
            </script>
          </material>
        </visual>
        <gravity>1</gravity>
        <velocity_decay/>
        <self_collide>0</self_collide>
        <enable_wind>0</enable_wind>
        <kinematic>0</kinematic>
      </link>
      <link name='/imu_link'>
        <pose frame=''>0 0 0 0 -0 0</pose>
        <inertial>
          <pose frame=''>0 0 0 0 -0 0</pose>
          <mass>0.015</mass>
          <inertia>
            <ixx>1e-05</ixx>
            <ixy>0</ixy>
            <ixz>0</ixz>
            <iyy>1e-05</iyy>
            <iyz>0</iyz>
            <izz>1e-05</izz>
          </inertia>
        </inertial>
        <self_collide>0</self_collide>
        <enable_wind>0</enable_wind>
        <kinematic>0</kinematic>
      </link>
      <joint name='/imu_joint' type='revolute'>
        <child>/imu_link</child>
        <parent>base_link</parent>
        <axis>
          <xyz>1 0 0</xyz>
          <limit>
            <lower>0</lower>
            <upper>0</upper>
            <effort>0</effort>
            <velocity>0</velocity>
          </limit>
          <dynamics>
            <spring_reference>0</spring_reference>
            <spring_stiffness>0</spring_stiffness>
          </dynamics>
          <use_parent_model_frame>1</use_parent_model_frame>
        </axis>
      </joint>
      <link name='rotor_0'>
        <pose frame=''>0.13 -0.22 0.023 0 -0 0</pose>
        <inertial>
          <pose frame=''>0 0 0 0 -0 0</pose>
          <mass>0.005</mass>
          <inertia>
            <ixx>9.75e-07</ixx>
            <ixy>0</ixy>
            <ixz>0</ixz>
            <iyy>0.000273104</iyy>
            <iyz>0</iyz>
            <izz>0.000274004</izz>
          </inertia>
        </inertial>
        <collision name='rotor_0_collision'>
          <pose frame=''>0 0 0 0 -0 0</pose>
          <geometry>
            <cylinder>
              <length>0.005</length>
              <radius>0.128</radius>
            </cylinder>
          </geometry>
          <surface>
            <contact>
              <ode/>
            </contact>
            <friction>
              <ode/>
              <torsional>
                <ode/>
              </torsional>
            </friction>
            <bounce/>
          </surface>
          <max_contacts>10</max_contacts>
        </collision>
        <visual name='rotor_0_visual'>
          <pose frame=''>0 0 0 0 -0 0</pose>
          <geometry>
            <mesh>
              <scale>1 1 1</scale>
              <uri>model://rotors_description/meshes/iris_prop_ccw.dae</uri>
            </mesh>
          </geometry>
          <material>
            <script>
              <name>Gazebo/Blue</name>
              <uri>file://media/materials/scripts/gazebo.material</uri>
            </script>
          </material>
        </visual>
        <gravity>1</gravity>
        <velocity_decay/>
        <self_collide>0</self_collide>
        <enable_wind>0</enable_wind>
        <kinematic>0</kinematic>
      </link>
      <joint name='rotor_0_joint' type='revolute'>
        <child>rotor_0</child>
        <parent>base_link</parent>
        <axis>
          <xyz>0 0 1</xyz>
          <limit>
            <lower>-1e+16</lower>
            <upper>1e+16</upper>
          </limit>
          <dynamics>
            <spring_reference>0</spring_reference>
            <spring_stiffness>0</spring_stiffness>
          </dynamics>
          <use_parent_model_frame>1</use_parent_model_frame>
        </axis>
      </joint>
      <link name='rotor_1'>
        <pose frame=''>-0.13 0.2 0.023 0 -0 0</pose>
        <inertial>
          <pose frame=''>0 0 0 0 -0 0</pose>
          <mass>0.005</mass>
          <inertia>
            <ixx>9.75e-07</ixx>
            <ixy>0</ixy>
            <ixz>0</ixz>
            <iyy>0.000273104</iyy>
            <iyz>0</iyz>
            <izz>0.000274004</izz>
          </inertia>
        </inertial>
        <collision name='rotor_1_collision'>
          <pose frame=''>0 0 0 0 -0 0</pose>
          <geometry>
            <cylinder>
              <length>0.005</length>
              <radius>0.128</radius>
            </cylinder>
          </geometry>
          <surface>
            <contact>
              <ode/>
            </contact>
            <friction>
              <ode/>
              <torsional>
                <ode/>
              </torsional>
            </friction>
            <bounce/>
          </surface>
          <max_contacts>10</max_contacts>
        </collision>
        <visual name='rotor_1_visual'>
          <pose frame=''>0 0 0 0 -0 0</pose>
          <geometry>
            <mesh>
              <scale>1 1 1</scale>
              <uri>model://rotors_description/meshes/iris_prop_ccw.dae</uri>
            </mesh>
          </geometry>
          <material>
            <script>
              <name>Gazebo/DarkGrey</name>
              <uri>file://media/materials/scripts/gazebo.material</uri>
            </script>
          </material>
        </visual>
        <gravity>1</gravity>
        <velocity_decay/>
        <self_collide>0</self_collide>
        <enable_wind>0</enable_wind>
        <kinematic>0</kinematic>
      </link>
      <joint name='rotor_1_joint' type='revolute'>
        <child>rotor_1</child>
        <parent>base_link</parent>
        <axis>
          <xyz>0 0 1</xyz>
          <limit>
            <lower>-1e+16</lower>
            <upper>1e+16</upper>
          </limit>
          <dynamics>
            <spring_reference>0</spring_reference>
            <spring_stiffness>0</spring_stiffness>
          </dynamics>
          <use_parent_model_frame>1</use_parent_model_frame>
        </axis>
      </joint>
      <link name='rotor_2'>
        <pose frame=''>0.13 0.22 0.023 0 -0 0</pose>
        <inertial>
          <pose frame=''>0 0 0 0 -0 0</pose>
          <mass>0.005</mass>
          <inertia>
            <ixx>9.75e-07</ixx>
            <ixy>0</ixy>
            <ixz>0</ixz>
            <iyy>0.000273104</iyy>
            <iyz>0</iyz>
            <izz>0.000274004</izz>
          </inertia>
        </inertial>
        <collision name='rotor_2_collision'>
          <pose frame=''>0 0 0 0 -0 0</pose>
          <geometry>
            <cylinder>
              <length>0.005</length>
              <radius>0.128</radius>
            </cylinder>
          </geometry>
          <surface>
            <contact>
              <ode/>
            </contact>
            <friction>
              <ode/>
              <torsional>
                <ode/>
              </torsional>
            </friction>
            <bounce/>
          </surface>
          <max_contacts>10</max_contacts>
        </collision>
        <visual name='rotor_2_visual'>
          <pose frame=''>0 0 0 0 -0 0</pose>
          <geometry>
            <mesh>
              <scale>1 1 1</scale>
              <uri>model://rotors_description/meshes/iris_prop_cw.dae</uri>
            </mesh>
          </geometry>
          <material>
            <script>
              <name>Gazebo/Blue</name>
              <uri>file://media/materials/scripts/gazebo.material</uri>
            </script>
          </material>
        </visual>
        <gravity>1</gravity>
        <velocity_decay/>
        <self_collide>0</self_collide>
        <enable_wind>0</enable_wind>
        <kinematic>0</kinematic>
      </link>
      <joint name='rotor_2_joint' type='revolute'>
        <child>rotor_2</child>
        <parent>base_link</parent>
        <axis>
          <xyz>0 0 1</xyz>
          <limit>
            <lower>-1e+16</lower>
            <upper>1e+16</upper>
          </limit>
          <dynamics>
            <spring_reference>0</spring_reference>
            <spring_stiffness>0</spring_stiffness>
          </dynamics>
          <use_parent_model_frame>1</use_parent_model_frame>
        </axis>
      </joint>
      <link name='rotor_3'>
        <pose frame=''>-0.13 -0.2 0.023 0 -0 0</pose>
        <inertial>
          <pose frame=''>0 0 0 0 -0 0</pose>
          <mass>0.005</mass>
          <inertia>
            <ixx>9.75e-07</ixx>
            <ixy>0</ixy>
            <ixz>0</ixz>
            <iyy>0.000273104</iyy>
            <iyz>0</iyz>
            <izz>0.000274004</izz>
          </inertia>
        </inertial>
        <collision name='rotor_3_collision'>
          <pose frame=''>0 0 0 0 -0 0</pose>
          <geometry>
            <cylinder>
              <length>0.005</length>
              <radius>0.128</radius>
            </cylinder>
          </geometry>
          <surface>
            <contact>
              <ode/>
            </contact>
            <friction>
              <ode/>
              <torsional>
                <ode/>
              </torsional>
            </friction>
            <bounce/>
          </surface>
          <max_contacts>10</max_contacts>
        </collision>
        <visual name='rotor_3_visual'>
          <pose frame=''>0 0 0 0 -0 0</pose>
          <geometry>
            <mesh>
              <scale>1 1 1</scale>
              <uri>model://rotors_description/meshes/iris_prop_cw.dae</uri>
            </mesh>
          </geometry>
          <material>
            <script>
              <name>Gazebo/DarkGrey</name>
              <uri>file://media/materials/scripts/gazebo.material</uri>
            </script>
          </material>
        </visual>
        <gravity>1</gravity>
        <velocity_decay/>
        <self_collide>0</self_collide>
        <enable_wind>0</enable_wind>
        <kinematic>0</kinematic>
      </link>
      <joint name='rotor_3_joint' type='revolute'>
        <child>rotor_3</child>
        <parent>base_link</parent>
        <axis>
          <xyz>0 0 1</xyz>
          <limit>
            <lower>-1e+16</lower>
            <upper>1e+16</upper>
          </limit>
          <dynamics>
            <spring_reference>0</spring_reference>
            <spring_stiffness>0</spring_stiffness>
          </dynamics>
          <use_parent_model_frame>1</use_parent_model_frame>
        </axis>
      </joint>
      <plugin name='rosbag' filename='libgazebo_multirotor_base_plugin.so'>
        <robotNamespace/>
        <linkName>base_link</linkName>
        <rotorVelocitySlowdownSim>10</rotorVelocitySlowdownSim>
      </plugin>
      <plugin name='front_right_motor_model' filename='libgazebo_motor_model.so'>
        <robotNamespace/>
        <jointName>rotor_0_joint</jointName>
        <linkName>rotor_0</linkName>
        <turningDirection>ccw</turningDirection>
        <timeConstantUp>0.0125</timeConstantUp>
        <timeConstantDown>0.025</timeConstantDown>
        <maxRotVelocity>1100</maxRotVelocity>
        <motorConstant>8.54858e-06</motorConstant>
        <momentConstant>0.06</momentConstant>
        <commandSubTopic>/gazebo/command/motor_speed</commandSubTopic>
        <motorNumber>0</motorNumber>
        <rotorDragCoefficient>0.000806428</rotorDragCoefficient>
        <rollingMomentCoefficient>1e-06</rollingMomentCoefficient>
        <motorSpeedPubTopic>/motor_speed/0</motorSpeedPubTopic>
        <rotorVelocitySlowdownSim>10</rotorVelocitySlowdownSim>
      </plugin>
      <plugin name='back_left_motor_model' filename='libgazebo_motor_model.so'>
        <robotNamespace/>
        <jointName>rotor_1_joint</jointName>
        <linkName>rotor_1</linkName>
        <turningDirection>ccw</turningDirection>
        <timeConstantUp>0.0125</timeConstantUp>
        <timeConstantDown>0.025</timeConstantDown>
        <maxRotVelocity>1100</maxRotVelocity>
        <motorConstant>8.54858e-06</motorConstant>
        <momentConstant>0.06</momentConstant>
        <commandSubTopic>/gazebo/command/motor_speed</commandSubTopic>
        <motorNumber>1</motorNumber>
        <rotorDragCoefficient>0.000806428</rotorDragCoefficient>
        <rollingMomentCoefficient>1e-06</rollingMomentCoefficient>
        <motorSpeedPubTopic>/motor_speed/1</motorSpeedPubTopic>
        <rotorVelocitySlowdownSim>10</rotorVelocitySlowdownSim>
      </plugin>
      <plugin name='front_left_motor_model' filename='libgazebo_motor_model.so'>
        <robotNamespace/>
        <jointName>rotor_2_joint</jointName>
        <linkName>rotor_2</linkName>
        <turningDirection>cw</turningDirection>
        <timeConstantUp>0.0125</timeConstantUp>
        <timeConstantDown>0.025</timeConstantDown>
        <maxRotVelocity>1100</maxRotVelocity>
        <motorConstant>8.54858e-06</motorConstant>
        <momentConstant>0.06</momentConstant>
        <commandSubTopic>/gazebo/command/motor_speed</commandSubTopic>
        <motorNumber>2</motorNumber>
        <rotorDragCoefficient>0.000806428</rotorDragCoefficient>
        <rollingMomentCoefficient>1e-06</rollingMomentCoefficient>
        <motorSpeedPubTopic>/motor_speed/2</motorSpeedPubTopic>
        <rotorVelocitySlowdownSim>10</rotorVelocitySlowdownSim>
      </plugin>
      <plugin name='back_right_motor_model' filename='libgazebo_motor_model.so'>
        <robotNamespace/>
        <jointName>rotor_3_joint</jointName>
        <linkName>rotor_3</linkName>
        <turningDirection>cw</turningDirection>
        <timeConstantUp>0.0125</timeConstantUp>
        <timeConstantDown>0.025</timeConstantDown>
        <maxRotVelocity>1100</maxRotVelocity>
        <motorConstant>8.54858e-06</motorConstant>
        <momentConstant>0.06</momentConstant>
        <commandSubTopic>/gazebo/command/motor_speed</commandSubTopic>
        <motorNumber>3</motorNumber>
        <rotorDragCoefficient>0.000806428</rotorDragCoefficient>
        <rollingMomentCoefficient>1e-06</rollingMomentCoefficient>
        <motorSpeedPubTopic>/motor_speed/3</motorSpeedPubTopic>
        <rotorVelocitySlowdownSim>10</rotorVelocitySlowdownSim>
      </plugin>
      <plugin name='gps_plugin' filename='libgazebo_gps_plugin.so'>
        <robotNamespace/>
        <gpsNoise>1</gpsNoise>
      </plugin>
      <plugin name='mavlink_interface' filename='libgazebo_mavlink_interface.so'>
        <robotNamespace/>
        <imuSubTopic>/imu</imuSubTopic>
        <gpsSubTopic>/gps</gpsSubTopic>
        <mavlink_addr>INADDR_ANY</mavlink_addr>
        <mavlink_udp_port>14560</mavlink_udp_port>
        <serialEnabled>0</serialEnabled>
        <serialDevice>/dev/ttyACM0</serialDevice>
        <baudRate>921600</baudRate>
        <qgc_addr>INADDR_ANY</qgc_addr>
        <qgc_udp_port>14550</qgc_udp_port>
        <hil_mode>0</hil_mode>
        <hil_state_level>0</hil_state_level>
        <vehicle_is_tailsitter>0</vehicle_is_tailsitter>
        <motorSpeedCommandPubTopic>/gazebo/command/motor_speed</motorSpeedCommandPubTopic>
        <control_channels>
          <channel name='rotor1'>
            <input_index>0</input_index>
            <input_offset>0</input_offset>
            <input_scaling>1000</input_scaling>
            <zero_position_disarmed>0</zero_position_disarmed>
            <zero_position_armed>100</zero_position_armed>
            <joint_control_type>velocity</joint_control_type>
          </channel>
          <channel name='rotor2'>
            <input_index>1</input_index>
            <input_offset>0</input_offset>
            <input_scaling>1000</input_scaling>
            <zero_position_disarmed>0</zero_position_disarmed>
            <zero_position_armed>100</zero_position_armed>
            <joint_control_type>velocity</joint_control_type>
          </channel>
          <channel name='rotor3'>
            <input_index>2</input_index>
            <input_offset>0</input_offset>
            <input_scaling>1000</input_scaling>
            <zero_position_disarmed>0</zero_position_disarmed>
            <zero_position_armed>100</zero_position_armed>
            <joint_control_type>velocity</joint_control_type>
          </channel>
          <channel name='rotor4'>
            <input_index>3</input_index>
            <input_offset>0</input_offset>
            <input_scaling>1000</input_scaling>
            <zero_position_disarmed>0</zero_position_disarmed>
            <zero_position_armed>100</zero_position_armed>
            <joint_control_type>velocity</joint_control_type>
          </channel>
          <channel name='rotor5'>
            <input_index>4</input_index>
            <input_offset>1</input_offset>
            <input_scaling>324.6</input_scaling>
            <zero_position_disarmed>0</zero_position_disarmed>
            <zero_position_armed>0</zero_position_armed>
            <joint_control_type>velocity</joint_control_type>
            <joint_control_pid>
              <p>0.1</p>
              <i>0</i>
              <d>0</d>
              <iMax>0.0</iMax>
              <iMin>0.0</iMin>
              <cmdMax>2</cmdMax>
              <cmdMin>-2</cmdMin>
            </joint_control_pid>
            <joint_name>zephyr_delta_wing::propeller_joint</joint_name>
          </channel>
          <channel name='rotor6'>
            <input_index>5</input_index>
            <input_offset>0</input_offset>
            <input_scaling>0.524</input_scaling>
            <zero_position_disarmed>0</zero_position_disarmed>
            <zero_position_armed>0</zero_position_armed>
            <joint_control_type>position</joint_control_type>
            <joint_name>zephyr_delta_wing::flap_left_joint</joint_name>
            <joint_control_pid>
              <p>10.0</p>
              <i>0</i>
              <d>0</d>
              <iMax>0</iMax>
              <iMin>0</iMin>
              <cmdMax>20</cmdMax>
              <cmdMin>-20</cmdMin>
            </joint_control_pid>
          </channel>
          <channel name='rotor7'>
            <input_index>6</input_index>
            <input_offset>0</input_offset>
            <input_scaling>0.524</input_scaling>
            <zero_position_disarmed>0</zero_position_disarmed>
            <zero_position_armed>0</zero_position_armed>
            <joint_control_type>position</joint_control_type>
            <joint_name>zephyr_delta_wing::flap_right_joint</joint_name>
            <joint_control_pid>
              <p>10.0</p>
              <i>0</i>
              <d>0</d>
              <iMax>0</iMax>
              <iMin>0</iMin>
              <cmdMax>20</cmdMax>
              <cmdMin>-20</cmdMin>
            </joint_control_pid>
          </channel>
          <channel name='rotor8'>
            <input_index>7</input_index>
            <input_offset>0</input_offset>
            <input_scaling>0.524</input_scaling>
            <zero_position_disarmed>0</zero_position_disarmed>
            <zero_position_armed>0</zero_position_armed>
            <joint_control_type>position</joint_control_type>
          </channel>
        </control_channels>
      </plugin>
      <static>0</static>
      <plugin name='rotors_gazebo_imu_plugin' filename='libgazebo_imu_plugin.so'>
        <robotNamespace/>
        <linkName>/imu_link</linkName>
        <imuTopic>/imu</imuTopic>
        <gyroscopeNoiseDensity>0.0003394</gyroscopeNoiseDensity>
        <gyroscopeRandomWalk>3.8785e-05</gyroscopeRandomWalk>
        <gyroscopeBiasCorrelationTime>1000.0</gyroscopeBiasCorrelationTime>
        <gyroscopeTurnOnBiasSigma>0.0087</gyroscopeTurnOnBiasSigma>
        <accelerometerNoiseDensity>0.004</accelerometerNoiseDensity>
        <accelerometerRandomWalk>0.006</accelerometerRandomWalk>
        <accelerometerBiasCorrelationTime>300.0</accelerometerBiasCorrelationTime>
        <accelerometerTurnOnBiasSigma>0.196</accelerometerTurnOnBiasSigma>
      </plugin>
      <pose frame=''>1.01 0.98 0.83 0 -0 1.14</pose>
    </model>
    <model name='uneven ground'>
      <static>1</static>
      <link name='link'>
        <collision name='collision'>
          <geometry>
            <heightmap>
              <uri>model://uneven_ground/materials/textures/terrain.png</uri>
              <size>80 80 2</size>
              <pos>0 0 0</pos>
              <texture>
                <size>10</size>
                <diffuse>__default__</diffuse>
                <normal>__default__</normal>
              </texture>
              <blend>
                <min_height>0</min_height>
                <fade_dist>0</fade_dist>
              </blend>
            </heightmap>
          </geometry>
          <max_contacts>10</max_contacts>
          <surface>
            <contact>
              <ode/>
            </contact>
            <bounce/>
            <friction>
              <torsional>
                <ode/>
              </torsional>
              <ode/>
            </friction>
          </surface>
        </collision>
        <visual name='visual'>
          <geometry>
            <heightmap>
              <use_terrain_paging>0</use_terrain_paging>
              <texture>
                <diffuse>model://uneven_ground/materials/textures/tarmac.png</diffuse>
                <normal>model://uneven_ground/materials/textures/flat_normal.png</normal>
                <size>1</size>
              </texture>
              <uri>model://uneven_ground/materials/textures/terrain.png</uri>
              <size>80 80 2</size>
              <pos>0 0 0</pos>
              <blend>
                <min_height>0</min_height>
                <fade_dist>0</fade_dist>
              </blend>
            </heightmap>
          </geometry>
        </visual>
        <self_collide>0</self_collide>
        <enable_wind>0</enable_wind>
        <kinematic>0</kinematic>
      </link>
    </model>
    <physics name='default_physics' default='0' type='ode'>
      <ode>
        <solver>
          <type>quick</type>
          <iters>10</iters>
          <sor>1.3</sor>
          <use_dynamic_moi_rescaling>0</use_dynamic_moi_rescaling>
        </solver>
        <constraints>
          <cfm>0</cfm>
          <erp>0.2</erp>
          <contact_max_correcting_vel>100</contact_max_correcting_vel>
          <contact_surface_layer>0.001</contact_surface_layer>
        </constraints>
      </ode>
      <max_step_size>0.002</max_step_size>
      <real_time_factor>1</real_time_factor>
      <real_time_update_rate>500</real_time_update_rate>
    </physics>
    <gui fullscreen='0'>
      <camera name='user_camera'>
        <pose frame=''>-12.9869 -2.53759 8.43811 0 0.190998 0.819428</pose>
        <view_controller>orbit</view_controller>
        <projection_type>perspective</projection_type>
      </camera>
    </gui>
    <gravity>0 0 -9.8066</gravity>
    <magnetic_field>6e-06 2.3e-05 -4.2e-05</magnetic_field>
    <atmosphere type='adiabatic'/>
    <scene>
      <ambient>0.4 0.4 0.4 1</ambient>
      <background>0.7 0.7 0.7 1</background>
      <shadows>1</shadows>
    </scene>
    <wind/>
    <spherical_coordinates>
      <surface_model>EARTH_WGS84</surface_model>
      <latitude_deg>0</latitude_deg>
      <longitude_deg>0</longitude_deg>
      <elevation>0</elevation>
      <heading_deg>0</heading_deg>
    </spherical_coordinates>
    <model name='fountain'>
      <static>1</static>
      <link name='link'>
        <collision name='collision'>
          <geometry>
            <mesh>
              <uri>model://fountain/meshes/fountain.dae</uri>
            </mesh>
          </geometry>
          <max_contacts>10</max_contacts>
          <surface>
            <contact>
              <ode/>
            </contact>
            <bounce/>
            <friction>
              <torsional>
                <ode/>
              </torsional>
              <ode/>
            </friction>
          </surface>
        </collision>
        <visual name='visual'>
          <geometry>
            <mesh>
              <uri>model://fountain/meshes/fountain.dae</uri>
            </mesh>
          </geometry>
        </visual>
        <self_collide>0</self_collide>
        <enable_wind>0</enable_wind>
        <kinematic>0</kinematic>
      </link>
      <pose frame=''>-5.07686 9.28602 0 0 -0 0</pose>
    </model>
    <model name='apartment'>
      <static>1</static>
      <link name='link'>
        <collision name='collision'>
          <geometry>
            <mesh>
              <uri>model://apartment/meshes/apartment.dae</uri>
            </mesh>
          </geometry>
          <max_contacts>10</max_contacts>
          <surface>
            <contact>
              <ode/>
            </contact>
            <bounce/>
            <friction>
              <torsional>
                <ode/>
              </torsional>
              <ode/>
            </friction>
          </surface>
        </collision>
        <visual name='visual'>
          <geometry>
            <mesh>
              <uri>model://apartment/meshes/apartment.dae</uri>
            </mesh>
          </geometry>
        </visual>
        <self_collide>0</self_collide>
        <enable_wind>0</enable_wind>
        <kinematic>0</kinematic>
      </link>
      <pose frame=''>9.64435 22.5659 0 0 -0 0</pose>
    </model>
    <state world_name='default'>
      <sim_time>2099 684000000</sim_time>
      <real_time>2102 843226429</real_time>
      <wall_time>1540684468 885456272</wall_time>
      <iterations>1049842</iterations>
      <model name='apartment'>
        <pose frame=''>-2.05616 22.5659 1.08864 0 -0 0</pose>
        <scale>1 1 1</scale>
        <link name='link'>
          <pose frame=''>-2.05616 22.5659 1.08864 0 -0 0</pose>
          <velocity>0 0 0 0 -0 0</velocity>
          <acceleration>0 0 0 0 -0 0</acceleration>
          <wrench>0 0 0 0 -0 0</wrench>
        </link>
      </model>
      <model name='fountain'>
        <pose frame=''>-12.7808 9.28602 1.98877 0 -0 0</pose>
        <scale>1 1 1</scale>
        <link name='link'>
          <pose frame=''>-12.7808 9.28602 1.98877 0 -0 0</pose>
          <velocity>0 0 0 0 -0 0</velocity>
          <acceleration>0 0 0 0 -0 0</acceleration>
          <wrench>0 0 0 0 -0 0</wrench>
        </link>
      </model>
      <model name='iris'>
        <pose frame=''>0.03054 11.7739 3.50226 -1.55319 1.21956 0.018752</pose>
        <scale>1 1 1</scale>
        <link name='/imu_link'>
          <pose frame=''>0.030543 11.7739 3.50226 -1.55321 1.21958 0.018727</pose>
          <velocity>-7.2e-05 -0.000317 0.000132 0.002995 -0.000264 -0.000216</velocity>
          <acceleration>-0.006689 -0.005237 0.009642 0.659633 0.002651 -1.785</acceleration>
          <wrench>-0.0001 -7.9e-05 0.000145 0 -0 0</wrench>
        </link>
        <link name='base_link'>
          <pose frame=''>0.03054 11.7739 3.50226 -1.55319 1.21956 0.018752</pose>
          <velocity>8.5e-05 -0.000248 -0.000107 0.001842 2.5e-05 0.00143</velocity>
          <acceleration>-8.8e-05 0.000207 5.9e-05 0.000229 -0.423362 0.001076</acceleration>
          <wrench>-0.000133 0.00031 8.9e-05 0 -0 0</wrench>
        </link>
        <link name='rotor_0'>
          <pose frame=''>0.281784 11.7978 3.45601 -1.56135 -0.859359 -0.004926</pose>
          <velocity>-9.8e-05 0.000185 0.000257 2.90219 -0.041883 -2.45478</velocity>
          <acceleration>-0.073835 -0.005858 0.163392 2.88652 -0.253216 -2.05553</acceleration>
          <wrench>-0.000369 -2.9e-05 0.000817 0 -0 0</wrench>
        </link>
        <link name='rotor_1'>
          <pose frame=''>-0.20202 11.7961 3.55566 -1.56434 0.326073 0.004283</pose>
          <velocity>-0.000123 -0.000808 0.000119 3.11764 -0.575026 -3.07876</velocity>
          <acceleration>-0.088987 -0.063618 0.089973 -2.01775 -0.067477 -1.19025</acceleration>
          <wrench>-0.000445 -0.000318 0.00045 0 -0 0</wrench>
        </link>
        <link name='rotor_2'>
          <pose frame=''>-0.131365 11.7978 3.30465 -1.56297 0.665756 0.007032</pose>
          <velocity>-5.7e-05 -0.000108 0.000143 0.226747 -1.17969 -0.625402</velocity>
          <acceleration>-0.051467 0.004084 0.100986 1.74515 1.07873 -1.2561</acceleration>
          <wrench>-0.000257 2e-05 0.000505 0 -0 0</wrench>
        </link>
        <link name='rotor_3'>
          <pose frame=''>0.17357 11.7961 3.69326 -1.37473 -1.53966 -0.193728</pose>
          <velocity>-0.000162 -0.000539 0.000223 0.042219 0.462623 -0.111271</velocity>
          <acceleration>-0.110107 -0.071531 0.146419 1.21339 0.990138 -1.94704</acceleration>
          <wrench>-0.000551 -0.000358 0.000732 0 -0 0</wrench>
        </link>
      </model>
      <model name='uneven ground'>
        <pose frame=''>0 0 0 0 -0 0</pose>
        <scale>1 1 1</scale>
        <link name='link'>
          <pose frame=''>0 0 0 0 -0 0</pose>
          <velocity>0 0 0 0 -0 0</velocity>
          <acceleration>0 0 0 0 -0 0</acceleration>
          <wrench>0 0 0 0 -0 0</wrench>
        </link>
      </model>
      <light name='sun'>
        <pose frame=''>0.23053 -0.104972 19.1497 0 -0 0</pose>
      </light>
    </state>
  </world>
</sdf>
